2025-06-20 16:36:26 | INFO | Running sync for all tables
2025-06-20 16:36:26 | INFO | Starting external data sync process
2025-06-20 16:36:26 | INFO | Starting sync for table: sales
2025-06-20 16:36:26 | INFO | Last sync time for sales: None
2025-06-20 16:36:27 | ERROR | Error syncing table sales: (pymysql.err.OperationalError) (2003, "Can't connect to MySQL server on 'external-server.example.com' ([Errno 8] nodename nor servname provided, or not known)")
(Background on this error at: https://sqlalche.me/e/20/e3q8)
2025-06-20 16:36:27 | ERROR | Traceback (most recent call last):
  File "/Users/kunnath/Projects/EDEKA_Stepaniak/venv/lib/python3.13/site-packages/pymysql/connections.py", line 649, in connect
    sock = socket.create_connection(
        (self.host, self.port), self.connect_timeout, **kwargs
    )
  File "/opt/homebrew/Cellar/python@3.13/3.13.3/Frameworks/Python.framework/Versions/3.13/lib/python3.13/socket.py", line 840, in create_connection
    for res in getaddrinfo(host, port, 0, SOCK_STREAM):
               ~~~~~~~~~~~^^^^^^^^^^^^^^^^^^^^^^^^^^^^
  File "/opt/homebrew/Cellar/python@3.13/3.13.3/Frameworks/Python.framework/Versions/3.13/lib/python3.13/socket.py", line 977, in getaddrinfo
    for res in _socket.getaddrinfo(host, port, family, type, proto, flags):
               ~~~~~~~~~~~~~~~~~~~^^^^^^^^^^^^^^^^^^^^^^^^^^^^^^^^^^^^^^^^
socket.gaierror: [Errno 8] nodename nor servname provided, or not known

During handling of the above exception, another exception occurred:

Traceback (most recent call last):
  File "/Users/kunnath/Projects/EDEKA_Stepaniak/venv/lib/python3.13/site-packages/sqlalchemy/engine/base.py", line 145, in __init__
    self._dbapi_connection = engine.raw_connection()
                             ~~~~~~~~~~~~~~~~~~~~~^^
  File "/Users/kunnath/Projects/EDEKA_Stepaniak/venv/lib/python3.13/site-packages/sqlalchemy/engine/base.py", line 3297, in raw_connection
    return self.pool.connect()
           ~~~~~~~~~~~~~~~~~^^
  File "/Users/kunnath/Projects/EDEKA_Stepaniak/venv/lib/python3.13/site-packages/sqlalchemy/pool/base.py", line 449, in connect
    return _ConnectionFairy._checkout(self)
           ~~~~~~~~~~~~~~~~~~~~~~~~~~^^^^^^
  File "/Users/kunnath/Projects/EDEKA_Stepaniak/venv/lib/python3.13/site-packages/sqlalchemy/pool/base.py", line 1264, in _checkout
    fairy = _ConnectionRecord.checkout(pool)
  File "/Users/kunnath/Projects/EDEKA_Stepaniak/venv/lib/python3.13/site-packages/sqlalchemy/pool/base.py", line 713, in checkout
    rec = pool._do_get()
  File "/Users/kunnath/Projects/EDEKA_Stepaniak/venv/lib/python3.13/site-packages/sqlalchemy/pool/impl.py", line 179, in _do_get
    with util.safe_reraise():
         ~~~~~~~~~~~~~~~~~^^
  File "/Users/kunnath/Projects/EDEKA_Stepaniak/venv/lib/python3.13/site-packages/sqlalchemy/util/langhelpers.py", line 224, in __exit__
    raise exc_value.with_traceback(exc_tb)
  File "/Users/kunnath/Projects/EDEKA_Stepaniak/venv/lib/python3.13/site-packages/sqlalchemy/pool/impl.py", line 177, in _do_get
    return self._create_connection()
           ~~~~~~~~~~~~~~~~~~~~~~~^^
  File "/Users/kunnath/Projects/EDEKA_Stepaniak/venv/lib/python3.13/site-packages/sqlalchemy/pool/base.py", line 390, in _create_connection
    return _ConnectionRecord(self)
  File "/Users/kunnath/Projects/EDEKA_Stepaniak/venv/lib/python3.13/site-packages/sqlalchemy/pool/base.py", line 675, in __init__
    self.__connect()
    ~~~~~~~~~~~~~~^^
  File "/Users/kunnath/Projects/EDEKA_Stepaniak/venv/lib/python3.13/site-packages/sqlalchemy/pool/base.py", line 901, in __connect
    with util.safe_reraise():
         ~~~~~~~~~~~~~~~~~^^
  File "/Users/kunnath/Projects/EDEKA_Stepaniak/venv/lib/python3.13/site-packages/sqlalchemy/util/langhelpers.py", line 224, in __exit__
    raise exc_value.with_traceback(exc_tb)
  File "/Users/kunnath/Projects/EDEKA_Stepaniak/venv/lib/python3.13/site-packages/sqlalchemy/pool/base.py", line 897, in __connect
    self.dbapi_connection = connection = pool._invoke_creator(self)
                                         ~~~~~~~~~~~~~~~~~~~~^^^^^^
  File "/Users/kunnath/Projects/EDEKA_Stepaniak/venv/lib/python3.13/site-packages/sqlalchemy/engine/create.py", line 646, in connect
    return dialect.connect(*cargs, **cparams)
           ~~~~~~~~~~~~~~~^^^^^^^^^^^^^^^^^^^
  File "/Users/kunnath/Projects/EDEKA_Stepaniak/venv/lib/python3.13/site-packages/sqlalchemy/engine/default.py", line 625, in connect
    return self.loaded_dbapi.connect(*cargs, **cparams)  # type: ignore[no-any-return]  # NOQA: E501
           ~~~~~~~~~~~~~~~~~~~~~~~~~^^^^^^^^^^^^^^^^^^^
  File "/Users/kunnath/Projects/EDEKA_Stepaniak/venv/lib/python3.13/site-packages/pymysql/connections.py", line 361, in __init__
    self.connect()
    ~~~~~~~~~~~~^^
  File "/Users/kunnath/Projects/EDEKA_Stepaniak/venv/lib/python3.13/site-packages/pymysql/connections.py", line 716, in connect
    raise exc
pymysql.err.OperationalError: (2003, "Can't connect to MySQL server on 'external-server.example.com' ([Errno 8] nodename nor servname provided, or not known)")

The above exception was the direct cause of the following exception:

Traceback (most recent call last):
  File "/Users/kunnath/Projects/EDEKA_Stepaniak/src/integrations/external_db_sync.py", line 217, in sync_table
    df = self._fetch_external_data(table_name, last_sync_time)
  File "/Users/kunnath/Projects/EDEKA_Stepaniak/src/integrations/external_db_sync.py", line 113, in _fetch_external_data
    result = session.execute(text(query), params)
  File "/Users/kunnath/Projects/EDEKA_Stepaniak/venv/lib/python3.13/site-packages/sqlalchemy/orm/session.py", line 2365, in execute
    return self._execute_internal(
           ~~~~~~~~~~~~~~~~~~~~~~^
        statement,
        ^^^^^^^^^^
    ...<4 lines>...
        _add_event=_add_event,
        ^^^^^^^^^^^^^^^^^^^^^^
    )
    ^
  File "/Users/kunnath/Projects/EDEKA_Stepaniak/venv/lib/python3.13/site-packages/sqlalchemy/orm/session.py", line 2241, in _execute_internal
    conn = self._connection_for_bind(bind)
  File "/Users/kunnath/Projects/EDEKA_Stepaniak/venv/lib/python3.13/site-packages/sqlalchemy/orm/session.py", line 2110, in _connection_for_bind
    return trans._connection_for_bind(engine, execution_options)
           ~~~~~~~~~~~~~~~~~~~~~~~~~~^^^^^^^^^^^^^^^^^^^^^^^^^^^
  File "<string>", line 2, in _connection_for_bind
  File "/Users/kunnath/Projects/EDEKA_Stepaniak/venv/lib/python3.13/site-packages/sqlalchemy/orm/state_changes.py", line 139, in _go
    ret_value = fn(self, *arg, **kw)
  File "/Users/kunnath/Projects/EDEKA_Stepaniak/venv/lib/python3.13/site-packages/sqlalchemy/orm/session.py", line 1189, in _connection_for_bind
    conn = bind.connect()
  File "/Users/kunnath/Projects/EDEKA_Stepaniak/venv/lib/python3.13/site-packages/sqlalchemy/engine/base.py", line 3273, in connect
    return self._connection_cls(self)
           ~~~~~~~~~~~~~~~~~~~~^^^^^^
  File "/Users/kunnath/Projects/EDEKA_Stepaniak/venv/lib/python3.13/site-packages/sqlalchemy/engine/base.py", line 147, in __init__
    Connection._handle_dbapi_exception_noconnection(
    ~~~~~~~~~~~~~~~~~~~~~~~~~~~~~~~~~~~~~~~~~~~~~~~^
        err, dialect, engine
        ^^^^^^^^^^^^^^^^^^^^
    )
    ^
  File "/Users/kunnath/Projects/EDEKA_Stepaniak/venv/lib/python3.13/site-packages/sqlalchemy/engine/base.py", line 2436, in _handle_dbapi_exception_noconnection
    raise sqlalchemy_exception.with_traceback(exc_info[2]) from e
  File "/Users/kunnath/Projects/EDEKA_Stepaniak/venv/lib/python3.13/site-packages/sqlalchemy/engine/base.py", line 145, in __init__
    self._dbapi_connection = engine.raw_connection()
                             ~~~~~~~~~~~~~~~~~~~~~^^
  File "/Users/kunnath/Projects/EDEKA_Stepaniak/venv/lib/python3.13/site-packages/sqlalchemy/engine/base.py", line 3297, in raw_connection
    return self.pool.connect()
           ~~~~~~~~~~~~~~~~~^^
  File "/Users/kunnath/Projects/EDEKA_Stepaniak/venv/lib/python3.13/site-packages/sqlalchemy/pool/base.py", line 449, in connect
    return _ConnectionFairy._checkout(self)
           ~~~~~~~~~~~~~~~~~~~~~~~~~~^^^^^^
  File "/Users/kunnath/Projects/EDEKA_Stepaniak/venv/lib/python3.13/site-packages/sqlalchemy/pool/base.py", line 1264, in _checkout
    fairy = _ConnectionRecord.checkout(pool)
  File "/Users/kunnath/Projects/EDEKA_Stepaniak/venv/lib/python3.13/site-packages/sqlalchemy/pool/base.py", line 713, in checkout
    rec = pool._do_get()
  File "/Users/kunnath/Projects/EDEKA_Stepaniak/venv/lib/python3.13/site-packages/sqlalchemy/pool/impl.py", line 179, in _do_get
    with util.safe_reraise():
         ~~~~~~~~~~~~~~~~~^^
  File "/Users/kunnath/Projects/EDEKA_Stepaniak/venv/lib/python3.13/site-packages/sqlalchemy/util/langhelpers.py", line 224, in __exit__
    raise exc_value.with_traceback(exc_tb)
  File "/Users/kunnath/Projects/EDEKA_Stepaniak/venv/lib/python3.13/site-packages/sqlalchemy/pool/impl.py", line 177, in _do_get
    return self._create_connection()
           ~~~~~~~~~~~~~~~~~~~~~~~^^
  File "/Users/kunnath/Projects/EDEKA_Stepaniak/venv/lib/python3.13/site-packages/sqlalchemy/pool/base.py", line 390, in _create_connection
    return _ConnectionRecord(self)
  File "/Users/kunnath/Projects/EDEKA_Stepaniak/venv/lib/python3.13/site-packages/sqlalchemy/pool/base.py", line 675, in __init__
    self.__connect()
    ~~~~~~~~~~~~~~^^
  File "/Users/kunnath/Projects/EDEKA_Stepaniak/venv/lib/python3.13/site-packages/sqlalchemy/pool/base.py", line 901, in __connect
    with util.safe_reraise():
         ~~~~~~~~~~~~~~~~~^^
  File "/Users/kunnath/Projects/EDEKA_Stepaniak/venv/lib/python3.13/site-packages/sqlalchemy/util/langhelpers.py", line 224, in __exit__
    raise exc_value.with_traceback(exc_tb)
  File "/Users/kunnath/Projects/EDEKA_Stepaniak/venv/lib/python3.13/site-packages/sqlalchemy/pool/base.py", line 897, in __connect
    self.dbapi_connection = connection = pool._invoke_creator(self)
                                         ~~~~~~~~~~~~~~~~~~~~^^^^^^
  File "/Users/kunnath/Projects/EDEKA_Stepaniak/venv/lib/python3.13/site-packages/sqlalchemy/engine/create.py", line 646, in connect
    return dialect.connect(*cargs, **cparams)
           ~~~~~~~~~~~~~~~^^^^^^^^^^^^^^^^^^^
  File "/Users/kunnath/Projects/EDEKA_Stepaniak/venv/lib/python3.13/site-packages/sqlalchemy/engine/default.py", line 625, in connect
    return self.loaded_dbapi.connect(*cargs, **cparams)  # type: ignore[no-any-return]  # NOQA: E501
           ~~~~~~~~~~~~~~~~~~~~~~~~~^^^^^^^^^^^^^^^^^^^
  File "/Users/kunnath/Projects/EDEKA_Stepaniak/venv/lib/python3.13/site-packages/pymysql/connections.py", line 361, in __init__
    self.connect()
    ~~~~~~~~~~~~^^
  File "/Users/kunnath/Projects/EDEKA_Stepaniak/venv/lib/python3.13/site-packages/pymysql/connections.py", line 716, in connect
    raise exc
sqlalchemy.exc.OperationalError: (pymysql.err.OperationalError) (2003, "Can't connect to MySQL server on 'external-server.example.com' ([Errno 8] nodename nor servname provided, or not known)")
(Background on this error at: https://sqlalche.me/e/20/e3q8)

2025-06-20 16:36:27 | INFO | Completed sync for table: sales
2025-06-20 16:36:27 | INFO | Starting sync for table: products
2025-06-20 16:36:27 | INFO | Last sync time for products: None
2025-06-20 16:36:27 | ERROR | Error syncing table products: (pymysql.err.OperationalError) (2003, "Can't connect to MySQL server on 'external-server.example.com' ([Errno 8] nodename nor servname provided, or not known)")
(Background on this error at: https://sqlalche.me/e/20/e3q8)
2025-06-20 16:36:27 | ERROR | Traceback (most recent call last):
  File "/Users/kunnath/Projects/EDEKA_Stepaniak/venv/lib/python3.13/site-packages/pymysql/connections.py", line 649, in connect
    sock = socket.create_connection(
        (self.host, self.port), self.connect_timeout, **kwargs
    )
  File "/opt/homebrew/Cellar/python@3.13/3.13.3/Frameworks/Python.framework/Versions/3.13/lib/python3.13/socket.py", line 840, in create_connection
    for res in getaddrinfo(host, port, 0, SOCK_STREAM):
               ~~~~~~~~~~~^^^^^^^^^^^^^^^^^^^^^^^^^^^^
  File "/opt/homebrew/Cellar/python@3.13/3.13.3/Frameworks/Python.framework/Versions/3.13/lib/python3.13/socket.py", line 977, in getaddrinfo
    for res in _socket.getaddrinfo(host, port, family, type, proto, flags):
               ~~~~~~~~~~~~~~~~~~~^^^^^^^^^^^^^^^^^^^^^^^^^^^^^^^^^^^^^^^^
socket.gaierror: [Errno 8] nodename nor servname provided, or not known

During handling of the above exception, another exception occurred:

Traceback (most recent call last):
  File "/Users/kunnath/Projects/EDEKA_Stepaniak/venv/lib/python3.13/site-packages/sqlalchemy/engine/base.py", line 145, in __init__
    self._dbapi_connection = engine.raw_connection()
                             ~~~~~~~~~~~~~~~~~~~~~^^
  File "/Users/kunnath/Projects/EDEKA_Stepaniak/venv/lib/python3.13/site-packages/sqlalchemy/engine/base.py", line 3297, in raw_connection
    return self.pool.connect()
           ~~~~~~~~~~~~~~~~~^^
  File "/Users/kunnath/Projects/EDEKA_Stepaniak/venv/lib/python3.13/site-packages/sqlalchemy/pool/base.py", line 449, in connect
    return _ConnectionFairy._checkout(self)
           ~~~~~~~~~~~~~~~~~~~~~~~~~~^^^^^^
  File "/Users/kunnath/Projects/EDEKA_Stepaniak/venv/lib/python3.13/site-packages/sqlalchemy/pool/base.py", line 1264, in _checkout
    fairy = _ConnectionRecord.checkout(pool)
  File "/Users/kunnath/Projects/EDEKA_Stepaniak/venv/lib/python3.13/site-packages/sqlalchemy/pool/base.py", line 713, in checkout
    rec = pool._do_get()
  File "/Users/kunnath/Projects/EDEKA_Stepaniak/venv/lib/python3.13/site-packages/sqlalchemy/pool/impl.py", line 179, in _do_get
    with util.safe_reraise():
         ~~~~~~~~~~~~~~~~~^^
  File "/Users/kunnath/Projects/EDEKA_Stepaniak/venv/lib/python3.13/site-packages/sqlalchemy/util/langhelpers.py", line 224, in __exit__
    raise exc_value.with_traceback(exc_tb)
  File "/Users/kunnath/Projects/EDEKA_Stepaniak/venv/lib/python3.13/site-packages/sqlalchemy/pool/impl.py", line 177, in _do_get
    return self._create_connection()
           ~~~~~~~~~~~~~~~~~~~~~~~^^
  File "/Users/kunnath/Projects/EDEKA_Stepaniak/venv/lib/python3.13/site-packages/sqlalchemy/pool/base.py", line 390, in _create_connection
    return _ConnectionRecord(self)
  File "/Users/kunnath/Projects/EDEKA_Stepaniak/venv/lib/python3.13/site-packages/sqlalchemy/pool/base.py", line 675, in __init__
    self.__connect()
    ~~~~~~~~~~~~~~^^
  File "/Users/kunnath/Projects/EDEKA_Stepaniak/venv/lib/python3.13/site-packages/sqlalchemy/pool/base.py", line 901, in __connect
    with util.safe_reraise():
         ~~~~~~~~~~~~~~~~~^^
  File "/Users/kunnath/Projects/EDEKA_Stepaniak/venv/lib/python3.13/site-packages/sqlalchemy/util/langhelpers.py", line 224, in __exit__
    raise exc_value.with_traceback(exc_tb)
  File "/Users/kunnath/Projects/EDEKA_Stepaniak/venv/lib/python3.13/site-packages/sqlalchemy/pool/base.py", line 897, in __connect
    self.dbapi_connection = connection = pool._invoke_creator(self)
                                         ~~~~~~~~~~~~~~~~~~~~^^^^^^
  File "/Users/kunnath/Projects/EDEKA_Stepaniak/venv/lib/python3.13/site-packages/sqlalchemy/engine/create.py", line 646, in connect
    return dialect.connect(*cargs, **cparams)
           ~~~~~~~~~~~~~~~^^^^^^^^^^^^^^^^^^^
  File "/Users/kunnath/Projects/EDEKA_Stepaniak/venv/lib/python3.13/site-packages/sqlalchemy/engine/default.py", line 625, in connect
    return self.loaded_dbapi.connect(*cargs, **cparams)  # type: ignore[no-any-return]  # NOQA: E501
           ~~~~~~~~~~~~~~~~~~~~~~~~~^^^^^^^^^^^^^^^^^^^
  File "/Users/kunnath/Projects/EDEKA_Stepaniak/venv/lib/python3.13/site-packages/pymysql/connections.py", line 361, in __init__
    self.connect()
    ~~~~~~~~~~~~^^
  File "/Users/kunnath/Projects/EDEKA_Stepaniak/venv/lib/python3.13/site-packages/pymysql/connections.py", line 716, in connect
    raise exc
pymysql.err.OperationalError: (2003, "Can't connect to MySQL server on 'external-server.example.com' ([Errno 8] nodename nor servname provided, or not known)")

The above exception was the direct cause of the following exception:

Traceback (most recent call last):
  File "/Users/kunnath/Projects/EDEKA_Stepaniak/src/integrations/external_db_sync.py", line 217, in sync_table
    df = self._fetch_external_data(table_name, last_sync_time)
  File "/Users/kunnath/Projects/EDEKA_Stepaniak/src/integrations/external_db_sync.py", line 113, in _fetch_external_data
    result = session.execute(text(query), params)
  File "/Users/kunnath/Projects/EDEKA_Stepaniak/venv/lib/python3.13/site-packages/sqlalchemy/orm/session.py", line 2365, in execute
    return self._execute_internal(
           ~~~~~~~~~~~~~~~~~~~~~~^
        statement,
        ^^^^^^^^^^
    ...<4 lines>...
        _add_event=_add_event,
        ^^^^^^^^^^^^^^^^^^^^^^
    )
    ^
  File "/Users/kunnath/Projects/EDEKA_Stepaniak/venv/lib/python3.13/site-packages/sqlalchemy/orm/session.py", line 2241, in _execute_internal
    conn = self._connection_for_bind(bind)
  File "/Users/kunnath/Projects/EDEKA_Stepaniak/venv/lib/python3.13/site-packages/sqlalchemy/orm/session.py", line 2110, in _connection_for_bind
    return trans._connection_for_bind(engine, execution_options)
           ~~~~~~~~~~~~~~~~~~~~~~~~~~^^^^^^^^^^^^^^^^^^^^^^^^^^^
  File "<string>", line 2, in _connection_for_bind
  File "/Users/kunnath/Projects/EDEKA_Stepaniak/venv/lib/python3.13/site-packages/sqlalchemy/orm/state_changes.py", line 139, in _go
    ret_value = fn(self, *arg, **kw)
  File "/Users/kunnath/Projects/EDEKA_Stepaniak/venv/lib/python3.13/site-packages/sqlalchemy/orm/session.py", line 1189, in _connection_for_bind
    conn = bind.connect()
  File "/Users/kunnath/Projects/EDEKA_Stepaniak/venv/lib/python3.13/site-packages/sqlalchemy/engine/base.py", line 3273, in connect
    return self._connection_cls(self)
           ~~~~~~~~~~~~~~~~~~~~^^^^^^
  File "/Users/kunnath/Projects/EDEKA_Stepaniak/venv/lib/python3.13/site-packages/sqlalchemy/engine/base.py", line 147, in __init__
    Connection._handle_dbapi_exception_noconnection(
    ~~~~~~~~~~~~~~~~~~~~~~~~~~~~~~~~~~~~~~~~~~~~~~~^
        err, dialect, engine
        ^^^^^^^^^^^^^^^^^^^^
    )
    ^
  File "/Users/kunnath/Projects/EDEKA_Stepaniak/venv/lib/python3.13/site-packages/sqlalchemy/engine/base.py", line 2436, in _handle_dbapi_exception_noconnection
    raise sqlalchemy_exception.with_traceback(exc_info[2]) from e
  File "/Users/kunnath/Projects/EDEKA_Stepaniak/venv/lib/python3.13/site-packages/sqlalchemy/engine/base.py", line 145, in __init__
    self._dbapi_connection = engine.raw_connection()
                             ~~~~~~~~~~~~~~~~~~~~~^^
  File "/Users/kunnath/Projects/EDEKA_Stepaniak/venv/lib/python3.13/site-packages/sqlalchemy/engine/base.py", line 3297, in raw_connection
    return self.pool.connect()
           ~~~~~~~~~~~~~~~~~^^
  File "/Users/kunnath/Projects/EDEKA_Stepaniak/venv/lib/python3.13/site-packages/sqlalchemy/pool/base.py", line 449, in connect
    return _ConnectionFairy._checkout(self)
           ~~~~~~~~~~~~~~~~~~~~~~~~~~^^^^^^
  File "/Users/kunnath/Projects/EDEKA_Stepaniak/venv/lib/python3.13/site-packages/sqlalchemy/pool/base.py", line 1264, in _checkout
    fairy = _ConnectionRecord.checkout(pool)
  File "/Users/kunnath/Projects/EDEKA_Stepaniak/venv/lib/python3.13/site-packages/sqlalchemy/pool/base.py", line 713, in checkout
    rec = pool._do_get()
  File "/Users/kunnath/Projects/EDEKA_Stepaniak/venv/lib/python3.13/site-packages/sqlalchemy/pool/impl.py", line 179, in _do_get
    with util.safe_reraise():
         ~~~~~~~~~~~~~~~~~^^
  File "/Users/kunnath/Projects/EDEKA_Stepaniak/venv/lib/python3.13/site-packages/sqlalchemy/util/langhelpers.py", line 224, in __exit__
    raise exc_value.with_traceback(exc_tb)
  File "/Users/kunnath/Projects/EDEKA_Stepaniak/venv/lib/python3.13/site-packages/sqlalchemy/pool/impl.py", line 177, in _do_get
    return self._create_connection()
           ~~~~~~~~~~~~~~~~~~~~~~~^^
  File "/Users/kunnath/Projects/EDEKA_Stepaniak/venv/lib/python3.13/site-packages/sqlalchemy/pool/base.py", line 390, in _create_connection
    return _ConnectionRecord(self)
  File "/Users/kunnath/Projects/EDEKA_Stepaniak/venv/lib/python3.13/site-packages/sqlalchemy/pool/base.py", line 675, in __init__
    self.__connect()
    ~~~~~~~~~~~~~~^^
  File "/Users/kunnath/Projects/EDEKA_Stepaniak/venv/lib/python3.13/site-packages/sqlalchemy/pool/base.py", line 901, in __connect
    with util.safe_reraise():
         ~~~~~~~~~~~~~~~~~^^
  File "/Users/kunnath/Projects/EDEKA_Stepaniak/venv/lib/python3.13/site-packages/sqlalchemy/util/langhelpers.py", line 224, in __exit__
    raise exc_value.with_traceback(exc_tb)
  File "/Users/kunnath/Projects/EDEKA_Stepaniak/venv/lib/python3.13/site-packages/sqlalchemy/pool/base.py", line 897, in __connect
    self.dbapi_connection = connection = pool._invoke_creator(self)
                                         ~~~~~~~~~~~~~~~~~~~~^^^^^^
  File "/Users/kunnath/Projects/EDEKA_Stepaniak/venv/lib/python3.13/site-packages/sqlalchemy/engine/create.py", line 646, in connect
    return dialect.connect(*cargs, **cparams)
           ~~~~~~~~~~~~~~~^^^^^^^^^^^^^^^^^^^
  File "/Users/kunnath/Projects/EDEKA_Stepaniak/venv/lib/python3.13/site-packages/sqlalchemy/engine/default.py", line 625, in connect
    return self.loaded_dbapi.connect(*cargs, **cparams)  # type: ignore[no-any-return]  # NOQA: E501
           ~~~~~~~~~~~~~~~~~~~~~~~~~^^^^^^^^^^^^^^^^^^^
  File "/Users/kunnath/Projects/EDEKA_Stepaniak/venv/lib/python3.13/site-packages/pymysql/connections.py", line 361, in __init__
    self.connect()
    ~~~~~~~~~~~~^^
  File "/Users/kunnath/Projects/EDEKA_Stepaniak/venv/lib/python3.13/site-packages/pymysql/connections.py", line 716, in connect
    raise exc
sqlalchemy.exc.OperationalError: (pymysql.err.OperationalError) (2003, "Can't connect to MySQL server on 'external-server.example.com' ([Errno 8] nodename nor servname provided, or not known)")
(Background on this error at: https://sqlalche.me/e/20/e3q8)

2025-06-20 16:36:27 | INFO | Completed sync for table: products
2025-06-20 16:36:27 | INFO | Starting sync for table: customers
2025-06-20 16:36:27 | INFO | Last sync time for customers: None
2025-06-20 16:36:27 | ERROR | Error syncing table customers: (pymysql.err.OperationalError) (2003, "Can't connect to MySQL server on 'external-server.example.com' ([Errno 8] nodename nor servname provided, or not known)")
(Background on this error at: https://sqlalche.me/e/20/e3q8)
2025-06-20 16:36:27 | ERROR | Traceback (most recent call last):
  File "/Users/kunnath/Projects/EDEKA_Stepaniak/venv/lib/python3.13/site-packages/pymysql/connections.py", line 649, in connect
    sock = socket.create_connection(
        (self.host, self.port), self.connect_timeout, **kwargs
    )
  File "/opt/homebrew/Cellar/python@3.13/3.13.3/Frameworks/Python.framework/Versions/3.13/lib/python3.13/socket.py", line 840, in create_connection
    for res in getaddrinfo(host, port, 0, SOCK_STREAM):
               ~~~~~~~~~~~^^^^^^^^^^^^^^^^^^^^^^^^^^^^
  File "/opt/homebrew/Cellar/python@3.13/3.13.3/Frameworks/Python.framework/Versions/3.13/lib/python3.13/socket.py", line 977, in getaddrinfo
    for res in _socket.getaddrinfo(host, port, family, type, proto, flags):
               ~~~~~~~~~~~~~~~~~~~^^^^^^^^^^^^^^^^^^^^^^^^^^^^^^^^^^^^^^^^
socket.gaierror: [Errno 8] nodename nor servname provided, or not known

During handling of the above exception, another exception occurred:

Traceback (most recent call last):
  File "/Users/kunnath/Projects/EDEKA_Stepaniak/venv/lib/python3.13/site-packages/sqlalchemy/engine/base.py", line 145, in __init__
    self._dbapi_connection = engine.raw_connection()
                             ~~~~~~~~~~~~~~~~~~~~~^^
  File "/Users/kunnath/Projects/EDEKA_Stepaniak/venv/lib/python3.13/site-packages/sqlalchemy/engine/base.py", line 3297, in raw_connection
    return self.pool.connect()
           ~~~~~~~~~~~~~~~~~^^
  File "/Users/kunnath/Projects/EDEKA_Stepaniak/venv/lib/python3.13/site-packages/sqlalchemy/pool/base.py", line 449, in connect
    return _ConnectionFairy._checkout(self)
           ~~~~~~~~~~~~~~~~~~~~~~~~~~^^^^^^
  File "/Users/kunnath/Projects/EDEKA_Stepaniak/venv/lib/python3.13/site-packages/sqlalchemy/pool/base.py", line 1264, in _checkout
    fairy = _ConnectionRecord.checkout(pool)
  File "/Users/kunnath/Projects/EDEKA_Stepaniak/venv/lib/python3.13/site-packages/sqlalchemy/pool/base.py", line 713, in checkout
    rec = pool._do_get()
  File "/Users/kunnath/Projects/EDEKA_Stepaniak/venv/lib/python3.13/site-packages/sqlalchemy/pool/impl.py", line 179, in _do_get
    with util.safe_reraise():
         ~~~~~~~~~~~~~~~~~^^
  File "/Users/kunnath/Projects/EDEKA_Stepaniak/venv/lib/python3.13/site-packages/sqlalchemy/util/langhelpers.py", line 224, in __exit__
    raise exc_value.with_traceback(exc_tb)
  File "/Users/kunnath/Projects/EDEKA_Stepaniak/venv/lib/python3.13/site-packages/sqlalchemy/pool/impl.py", line 177, in _do_get
    return self._create_connection()
           ~~~~~~~~~~~~~~~~~~~~~~~^^
  File "/Users/kunnath/Projects/EDEKA_Stepaniak/venv/lib/python3.13/site-packages/sqlalchemy/pool/base.py", line 390, in _create_connection
    return _ConnectionRecord(self)
  File "/Users/kunnath/Projects/EDEKA_Stepaniak/venv/lib/python3.13/site-packages/sqlalchemy/pool/base.py", line 675, in __init__
    self.__connect()
    ~~~~~~~~~~~~~~^^
  File "/Users/kunnath/Projects/EDEKA_Stepaniak/venv/lib/python3.13/site-packages/sqlalchemy/pool/base.py", line 901, in __connect
    with util.safe_reraise():
         ~~~~~~~~~~~~~~~~~^^
  File "/Users/kunnath/Projects/EDEKA_Stepaniak/venv/lib/python3.13/site-packages/sqlalchemy/util/langhelpers.py", line 224, in __exit__
    raise exc_value.with_traceback(exc_tb)
  File "/Users/kunnath/Projects/EDEKA_Stepaniak/venv/lib/python3.13/site-packages/sqlalchemy/pool/base.py", line 897, in __connect
    self.dbapi_connection = connection = pool._invoke_creator(self)
                                         ~~~~~~~~~~~~~~~~~~~~^^^^^^
  File "/Users/kunnath/Projects/EDEKA_Stepaniak/venv/lib/python3.13/site-packages/sqlalchemy/engine/create.py", line 646, in connect
    return dialect.connect(*cargs, **cparams)
           ~~~~~~~~~~~~~~~^^^^^^^^^^^^^^^^^^^
  File "/Users/kunnath/Projects/EDEKA_Stepaniak/venv/lib/python3.13/site-packages/sqlalchemy/engine/default.py", line 625, in connect
    return self.loaded_dbapi.connect(*cargs, **cparams)  # type: ignore[no-any-return]  # NOQA: E501
           ~~~~~~~~~~~~~~~~~~~~~~~~~^^^^^^^^^^^^^^^^^^^
  File "/Users/kunnath/Projects/EDEKA_Stepaniak/venv/lib/python3.13/site-packages/pymysql/connections.py", line 361, in __init__
    self.connect()
    ~~~~~~~~~~~~^^
  File "/Users/kunnath/Projects/EDEKA_Stepaniak/venv/lib/python3.13/site-packages/pymysql/connections.py", line 716, in connect
    raise exc
pymysql.err.OperationalError: (2003, "Can't connect to MySQL server on 'external-server.example.com' ([Errno 8] nodename nor servname provided, or not known)")

The above exception was the direct cause of the following exception:

Traceback (most recent call last):
  File "/Users/kunnath/Projects/EDEKA_Stepaniak/src/integrations/external_db_sync.py", line 217, in sync_table
    df = self._fetch_external_data(table_name, last_sync_time)
  File "/Users/kunnath/Projects/EDEKA_Stepaniak/src/integrations/external_db_sync.py", line 113, in _fetch_external_data
    result = session.execute(text(query), params)
  File "/Users/kunnath/Projects/EDEKA_Stepaniak/venv/lib/python3.13/site-packages/sqlalchemy/orm/session.py", line 2365, in execute
    return self._execute_internal(
           ~~~~~~~~~~~~~~~~~~~~~~^
        statement,
        ^^^^^^^^^^
    ...<4 lines>...
        _add_event=_add_event,
        ^^^^^^^^^^^^^^^^^^^^^^
    )
    ^
  File "/Users/kunnath/Projects/EDEKA_Stepaniak/venv/lib/python3.13/site-packages/sqlalchemy/orm/session.py", line 2241, in _execute_internal
    conn = self._connection_for_bind(bind)
  File "/Users/kunnath/Projects/EDEKA_Stepaniak/venv/lib/python3.13/site-packages/sqlalchemy/orm/session.py", line 2110, in _connection_for_bind
    return trans._connection_for_bind(engine, execution_options)
           ~~~~~~~~~~~~~~~~~~~~~~~~~~^^^^^^^^^^^^^^^^^^^^^^^^^^^
  File "<string>", line 2, in _connection_for_bind
  File "/Users/kunnath/Projects/EDEKA_Stepaniak/venv/lib/python3.13/site-packages/sqlalchemy/orm/state_changes.py", line 139, in _go
    ret_value = fn(self, *arg, **kw)
  File "/Users/kunnath/Projects/EDEKA_Stepaniak/venv/lib/python3.13/site-packages/sqlalchemy/orm/session.py", line 1189, in _connection_for_bind
    conn = bind.connect()
  File "/Users/kunnath/Projects/EDEKA_Stepaniak/venv/lib/python3.13/site-packages/sqlalchemy/engine/base.py", line 3273, in connect
    return self._connection_cls(self)
           ~~~~~~~~~~~~~~~~~~~~^^^^^^
  File "/Users/kunnath/Projects/EDEKA_Stepaniak/venv/lib/python3.13/site-packages/sqlalchemy/engine/base.py", line 147, in __init__
    Connection._handle_dbapi_exception_noconnection(
    ~~~~~~~~~~~~~~~~~~~~~~~~~~~~~~~~~~~~~~~~~~~~~~~^
        err, dialect, engine
        ^^^^^^^^^^^^^^^^^^^^
    )
    ^
  File "/Users/kunnath/Projects/EDEKA_Stepaniak/venv/lib/python3.13/site-packages/sqlalchemy/engine/base.py", line 2436, in _handle_dbapi_exception_noconnection
    raise sqlalchemy_exception.with_traceback(exc_info[2]) from e
  File "/Users/kunnath/Projects/EDEKA_Stepaniak/venv/lib/python3.13/site-packages/sqlalchemy/engine/base.py", line 145, in __init__
    self._dbapi_connection = engine.raw_connection()
                             ~~~~~~~~~~~~~~~~~~~~~^^
  File "/Users/kunnath/Projects/EDEKA_Stepaniak/venv/lib/python3.13/site-packages/sqlalchemy/engine/base.py", line 3297, in raw_connection
    return self.pool.connect()
           ~~~~~~~~~~~~~~~~~^^
  File "/Users/kunnath/Projects/EDEKA_Stepaniak/venv/lib/python3.13/site-packages/sqlalchemy/pool/base.py", line 449, in connect
    return _ConnectionFairy._checkout(self)
           ~~~~~~~~~~~~~~~~~~~~~~~~~~^^^^^^
  File "/Users/kunnath/Projects/EDEKA_Stepaniak/venv/lib/python3.13/site-packages/sqlalchemy/pool/base.py", line 1264, in _checkout
    fairy = _ConnectionRecord.checkout(pool)
  File "/Users/kunnath/Projects/EDEKA_Stepaniak/venv/lib/python3.13/site-packages/sqlalchemy/pool/base.py", line 713, in checkout
    rec = pool._do_get()
  File "/Users/kunnath/Projects/EDEKA_Stepaniak/venv/lib/python3.13/site-packages/sqlalchemy/pool/impl.py", line 179, in _do_get
    with util.safe_reraise():
         ~~~~~~~~~~~~~~~~~^^
  File "/Users/kunnath/Projects/EDEKA_Stepaniak/venv/lib/python3.13/site-packages/sqlalchemy/util/langhelpers.py", line 224, in __exit__
    raise exc_value.with_traceback(exc_tb)
  File "/Users/kunnath/Projects/EDEKA_Stepaniak/venv/lib/python3.13/site-packages/sqlalchemy/pool/impl.py", line 177, in _do_get
    return self._create_connection()
           ~~~~~~~~~~~~~~~~~~~~~~~^^
  File "/Users/kunnath/Projects/EDEKA_Stepaniak/venv/lib/python3.13/site-packages/sqlalchemy/pool/base.py", line 390, in _create_connection
    return _ConnectionRecord(self)
  File "/Users/kunnath/Projects/EDEKA_Stepaniak/venv/lib/python3.13/site-packages/sqlalchemy/pool/base.py", line 675, in __init__
    self.__connect()
    ~~~~~~~~~~~~~~^^
  File "/Users/kunnath/Projects/EDEKA_Stepaniak/venv/lib/python3.13/site-packages/sqlalchemy/pool/base.py", line 901, in __connect
    with util.safe_reraise():
         ~~~~~~~~~~~~~~~~~^^
  File "/Users/kunnath/Projects/EDEKA_Stepaniak/venv/lib/python3.13/site-packages/sqlalchemy/util/langhelpers.py", line 224, in __exit__
    raise exc_value.with_traceback(exc_tb)
  File "/Users/kunnath/Projects/EDEKA_Stepaniak/venv/lib/python3.13/site-packages/sqlalchemy/pool/base.py", line 897, in __connect
    self.dbapi_connection = connection = pool._invoke_creator(self)
                                         ~~~~~~~~~~~~~~~~~~~~^^^^^^
  File "/Users/kunnath/Projects/EDEKA_Stepaniak/venv/lib/python3.13/site-packages/sqlalchemy/engine/create.py", line 646, in connect
    return dialect.connect(*cargs, **cparams)
           ~~~~~~~~~~~~~~~^^^^^^^^^^^^^^^^^^^
  File "/Users/kunnath/Projects/EDEKA_Stepaniak/venv/lib/python3.13/site-packages/sqlalchemy/engine/default.py", line 625, in connect
    return self.loaded_dbapi.connect(*cargs, **cparams)  # type: ignore[no-any-return]  # NOQA: E501
           ~~~~~~~~~~~~~~~~~~~~~~~~~^^^^^^^^^^^^^^^^^^^
  File "/Users/kunnath/Projects/EDEKA_Stepaniak/venv/lib/python3.13/site-packages/pymysql/connections.py", line 361, in __init__
    self.connect()
    ~~~~~~~~~~~~^^
  File "/Users/kunnath/Projects/EDEKA_Stepaniak/venv/lib/python3.13/site-packages/pymysql/connections.py", line 716, in connect
    raise exc
sqlalchemy.exc.OperationalError: (pymysql.err.OperationalError) (2003, "Can't connect to MySQL server on 'external-server.example.com' ([Errno 8] nodename nor servname provided, or not known)")
(Background on this error at: https://sqlalche.me/e/20/e3q8)

2025-06-20 16:36:27 | INFO | Completed sync for table: customers
2025-06-20 16:36:27 | INFO | Sync completed in 0.22 seconds
2025-06-20 16:36:27 | INFO | Total records fetched: 0
2025-06-20 16:36:27 | INFO | Total records inserted: 0
2025-06-20 16:36:27 | INFO | Total records updated: 0
2025-06-20 16:36:27 | INFO | Total records failed: 0
2025-06-20 16:36:27 | INFO | Sync completed: {'fetched': 0, 'inserted': 0, 'updated': 0, 'failed': 0, 'duration': 0.21500229835510254}
